Workbook

Sheet tradicional (cálculo)
B1: CÁLCULO DE PRIMAS DE SEGUROS (TRADICIONAL)
B2: AÑOS DE VIGENCIA | D2: ='nuevo (cálculo)'!C3 -> 4
B3: 1er AÑO | F3: 2do AÑO | G3: Depreciación | H3: ='nuevo (cálculo)'!B6 -> 0.15 | J3: 3er AÑO | K3: Depreciación | L3: ='nuevo (cálculo)'!B7 -> 0.1 | N3: 4to. AÑO | O3: Depreciación | P3: ='nuevo (cálculo)'!B8 -> 0.1
B5: VALOR ASEGURADO | D5: =+'nuevo (cálculo)'!$C$6 -> 25290 | F5: VALOR ASEGURADO | H5: =+$D$5-(D5*H3) -> 21496.5 | J5: VALOR ASEGURADO | L5: =+$H$5-(H5*L3) -> 19346.85 | N5: VALOR ASEGURADO | P5: =+$L$5-(L5*P3) -> 17412.165
B6: TASA | C6: 0.03 | F6: TASA | G6: 0.03 | J6: TASA | K6: 0.03 | N6: TASA | O6: 0.03
B7: PRIMA NETA | D7: =+D5*C6 -> 758.7 | F7: PRIMA NETA | H7: =+H5*G6 -> 644.895 | J7: PRIMA NETA | L7: =+L5*K6 -> 580.4055 | N7: PRIMA NETA | P7: =+P5*O6 -> 522.36495
B8: SUPER DE BANCOS | C8: 0.035 | D8: =+D7*C8 -> 26.5545 | F8: SUPER DE BANCOS | G8: 0.035 | H8: =+H7*G8 -> 22.571325 | J8: SUPER DE BANCOS | K8: 0.035 | L8: =+L7*K8 -> 20.314193 | N8: SUPER DE BANCOS | O8: 0.035 | P8: =+P7*O8 -> 18.282773
B9: SEGURO CAMPESINO | C9: 0.005 | D9: =+D7*C9 -> 3.7935 | F9: SEGURO CAMPESINO | G9: 0.005 | H9: =+H7*G9 -> 3.224475 | J9: SEGURO CAMPESINO | K9: 0.005 | L9: =+L7*K9 -> 2.9020275 | N9: SEGURO CAMPESINO | O9: 0.005 | P9: =+P7*O9 -> 2.6118247
B10: DERECHOS DE EMISIÓN | D10: 6 | F10: DERECHOS DE EMISIÓN | H10: 6 | J10: DERECHOS DE EMISIÓN | L10: 6 | N10: DERECHOS DE EMISIÓN | P10: 6
B11: SUBTOTAL | D11: =+D8+D7+D9+D10 -> 795.048 | F11: SUBTOTAL | H11: =+H8+H7+H9+H10 -> 676.6908 | J11: SUBTOTAL | L11: =+L8+L7+L9+L10 -> 609.62172 | N11: SUBTOTAL | P11: =+P8+P7+P9+P10 -> 549.25955
B12: IVA | C12: 0.12 | D12: =+D11*C12 -> 95.40576 | F12: IVA | G12: 0.12 | H12: =+H11*G12 -> 81.202896 | J12: IVA | K12: 0.12 | L12: =+L11*K12 -> 73.154606 | N12: IVA | O12: 0.12 | P12: =+P11*O12 -> 65.911146
B13: PRIMA TOTAL | D13: =+D11+D12 -> 890.45376 | F13: PRIMA TOTAL | H13: =+H11+H12 -> 757.8937 | J13: PRIMA TOTAL | L13: =+L11+L12 -> 682.77633 | N13: PRIMA TOTAL | P13: =+P11+P12 -> 615.17069
D14: =+D13/12 -> 74.20448 | H14: =+H13/12 -> 63.157808 | L14: =+L13/12 -> 56.898027 | P14: =+P13/12 -> 51.264224
B16: VALOR DE SEGURO POR 4 AÑOS: | F16: =+D13+H13+L13+P13 -> 2946.2945
B18: PLAZO DE CRÉDITO | D18: =+D2*12 -> 48 | F18: =+F16/D18 -> 61.381135 | G18: CUOTA FIJA PROMEDIO
B22: CÁLCULO DE PRIMAS DE SEGUROS (NUEVO MODELO)
B23: AÑOS DE VIGENCIA | D23: ='nuevo (cálculo)'!C3 -> 4
B24: 1er AÑO | F24: 2do AÑO | G24: Depreciación | H24: ='nuevo (cálculo)'!B6 -> 0.15 | J24: 3er AÑO | K24: Depreciación | L24: ='nuevo (cálculo)'!B7 -> 0.1 | N24: 4to. AÑO | O24: Depreciación | P24: ='nuevo (cálculo)'!B8 -> 0.1
B26: VALOR ASEGURADO | D26: =+'nuevo (cálculo)'!$C$6 -> 25290 | F26: VALOR ASEGURADO | H26: =+$D$5-(D26*H24) -> 21496.5 | J26: VALOR ASEGURADO | L26: =+$H$5-(H26*L24) -> 19346.85 | N26: VALOR ASEGURADO | P26: =+$L$5-(L26*P24) -> 17412.165
B27: TASA | C27: 0.03 | F27: TASA | G27: 0.03 | J27: TASA | K27: 0.03 | N27: TASA | O27: 0.03
B28: PRIMA NETA | D28: =+SUM('nuevo (cálculo)'!C13:C24) -> 706.53937 | F28: PRIMA NETA | H28: =+SUM('nuevo (cálculo)'!C25:C36) -> 615.33731 | J28: PRIMA NETA | L28: =+SUM('nuevo (cálculo)'!C37:C48) -> 553.80358 | N28: PRIMA NETA | P28: =+SUM('nuevo (cálculo)'!C49:C60) -> 498.42322
B29: SUPER DE BANCOS | C29: 0.035 | D29: =+D28*C29 -> 24.728878 | F29: SUPER DE BANCOS | G29: 0.035 | H29: =+H28*G29 -> 21.536806 | J29: SUPER DE BANCOS | K29: 0.035 | L29: =+L28*K29 -> 19.383125 | N29: SUPER DE BANCOS | O29: 0.035 | P29: =+P28*O29 -> 17.444813
B30: SEGURO CAMPESINO | C30: 0.005 | D30: =+D28*C30 -> 3.5326969 | F30: SEGURO CAMPESINO | G30: 0.005 | H30: =+H28*G30 -> 3.0766866 | J30: SEGURO CAMPESINO | K30: 0.005 | L30: =+L28*K30 -> 2.7690179 | N30: SEGURO CAMPESINO | O30: 0.005 | P30: =+P28*O30 -> 2.4921161
B31: DERECHOS DE EMISIÓN | C31: 1 | D31: =+SUM('nuevo (cálculo)'!F13:F24) -> 6 | F31: DERECHOS DE EMISIÓN | G31: 1 | H31: =SUM('nuevo (cálculo)'!F25:F36) -> 6 | J31: DERECHOS DE EMISIÓN | K31: 1 | L31: =SUM('nuevo (cálculo)'!F37:F48) -> 6 | N31: DERECHOS DE EMISIÓN | O31: 1 | P31: =SUM('nuevo (cálculo)'!F49:F60) -> 6
B32: SUBTOTAL | D32: =+D29+D28+D30+D31 -> 740.80095 | F32: SUBTOTAL | H32: =+H29+H28+H30+H31 -> 645.9508 | J32: SUBTOTAL | L32: =+L29+L28+L30+L31 -> 581.95572 | N32: SUBTOTAL | P32: =+P29+P28+P30+P31 -> 524.36015
B33: IVA | C33: 0.12 | D33: =+D32*C33 -> 88.896114 | F33: IVA | G33: 0.12 | H33: =+H32*G33 -> 77.514097 | J33: IVA | K33: 0.12 | L33: =+L32*K33 -> 69.834687 | N33: IVA | O33: 0.12 | P33: =+P32*O33 -> 62.923218
B34: PRIMA TOTAL | D34: =+D32+D33 -> 829.69706 | F34: PRIMA TOTAL | H34: =+H32+H33 -> 723.4649 | J34: PRIMA TOTAL | L34: =+L32+L33 -> 651.79041 | N34: PRIMA TOTAL | P34: =+P32+P33 -> 587.28337
D35: =+D34/12 -> 69.141422 | H35: =+H34/12 -> 60.288742 | L35: =+L34/12 -> 54.315868 | P35: =+P34/12 -> 48.940281
B37: VALOR DE SEGURO POR 4 AÑOS: | F37: =+D34+H34+L34+P34 -> 2792.2357
B39: PLAZO DE CRÉDITO | D39: =+D23*12 -> 48 | F39: =+F37/D39 -> 58.171578 | G39: CUOTA FIJA PROMEDIO

Sheet nuevo (cálculo)
A1: NOMBRE DEL ASEGURADO: | C1: HORNA GONZALES JEYDY ESTHER
A2: VEHICULO: | C2: GREAT WALL
A3: AÑOS DE VIGENCIA | C3: 4
A5: AÑOS | B5: DEPRECIACIÓN | C5: VALORES ASEGURADOS | D5: VALOR ANUAL DE DEPRECIACIÓN | E5: VALOR ANUAL DE DEPRECIACIÓN MENSUAL | F5: TASA | H5: CUOTA FIJA (pago cliente) | I5: =AVERAGE(I13:I60) -> 58.171578
A6: 1er. Año | B6: 0.15 | C6: 25290 | D6: =+C6*B6 -> 3793.5 | E6: =+D6/12 -> 316.125 | F6: 0.03
A7: 2do. Año | B7: 0.1 | C7: =+C6-D6 -> 21496.5 | D7: =+C7*B7 -> 2149.65 | E7: =+D7/12 -> 179.1375 | F7: 0.03
A8: 3er. Año | B8: 0.1 | C8: =+C7-D7 -> 19346.85 | D8: =+C8*B8 -> 1934.685 | E8: =+D8/12 -> 161.22375 | F8: 0.03
A9: 4to. Año | B9: 0.1 | C9: =+C8-D8 -> 17412.165 | D9: =+C9*B9 -> 1741.2165 | E9: =+D9/12 -> 145.10137 | F9: 0.03
D11: 0.035 | E11: 0.005 | F11: 0.5 | H11: 0.12 | K11: NIVELACIÓN
A12: MES | B12: VALOR ASEGURADO | C12: PRIMA NETA MES | D12: SUPER DE BANCOS | E12: SEGURO CAMPESINO | F12: DERECHOS DE EMISIÓN | G12: SUBTOTAL | H12: IVA | I12: PRIMA TOTAL MES (COSTO REAL) | K12: CUOTA FIJA | L12: DIFERENCIA | M12: NIVELACIÓN ACUMULADA
A13: 1 | B13: =+C6 -> 25290 | C13: =+B13*($F$6/12) -> 63.225 | D13: =+C13*$D$11 -> 2.212875 | E13: =+C13*$E$11 -> 0.316125 | F13: =+$F$11 -> 0.5 | G13: =+SUM(C13:F13) -> 66.254 | H13: =+G13*$H$11 -> 7.95048 | I13: =+G13+H13 -> 74.20448 | K13: =$I$5 -> 58.171578 | L13: =K13-I13 -> -16.032902 | M13: =+L13 -> -16.032902
A14: 2 | B14: =+B13-E$6 -> 24973.875 | C14: =+B14*($F$6/12) -> 62.434688 | D14: =+C14*$D$11 -> 2.1852141 | E14: =+C14*$E$11 -> 0.31217344 | F14: =+$F$11 -> 0.5 | G14: =+SUM(C14:F14) -> 65.432075 | H14: =+G14*$H$11 -> 7.851849 | I14: =+G14+H14 -> 73.283924 | K14: =$I$5 -> 58.171578 | L14: =K14-I14 -> -15.112346 | M14: =+M13+L14 -> -31.145248
A15: 3 | B15: =+B14-E$6 -> 24657.75 | C15: =+B15*($F$6/12) -> 61.644375 | D15: =+C15*$D$11 -> 2.1575531 | E15: =+C15*$E$11 -> 0.30822188 | F15: =+$F$11 -> 0.5 | G15: =+SUM(C15:F15) -> 64.61015 | H15: =+G15*$H$11 -> 7.753218 | I15: =+G15+H15 -> 72.363368 | K15: =$I$5 -> 58.171578 | L15: =K15-I15 -> -14.19179 | M15: =+M14+L15 -> -45.337038
A16: 4 | B16: =+B15-E$6 -> 24341.625 | C16: =+B16*($F$6/12) -> 60.854062 | D16: =+C16*$D$11 -> 2.1298922 | E16: =+C16*$E$11 -> 0.30427031 | F16: =+$F$11 -> 0.5 | G16: =+SUM(C16:F16) -> 63.788225 | H16: =+G16*$H$11 -> 7.654587 | I16: =+G16+H16 -> 71.442812 | K16: =$I$5 -> 58.171578 | L16: =K16-I16 -> -13.271234 | M16: =+M15+L16 -> -58.608272
A17: 5 | B17: =+B16-E$6 -> 24025.5 | C17: =+B17*($F$6/12) -> 60.06375 | D17: =+C17*$D$11 -> 2.1022312 | E17: =+C17*$E$11 -> 0.30031875 | F17: =+$F$11 -> 0.5 | G17: =+SUM(C17:F17) -> 62.9663 | H17: =+G17*$H$11 -> 7.555956 | I17: =+G17+H17 -> 70.522256 | K17: =$I$5 -> 58.171578 | L17: =K17-I17 -> -12.350678 | M17: =+M16+L17 -> -70.95895
A18: 6 | B18: =+B17-E$6 -> 23709.375 | C18: =+B18*($F$6/12) -> 59.273438 | D18: =+C18*$D$11 -> 2.0745703 | E18: =+C18*$E$11 -> 0.29636719 | F18: =+$F$11 -> 0.5 | G18: =+SUM(C18:F18) -> 62.144375 | H18: =+G18*$H$11 -> 7.457325 | I18: =+G18+H18 -> 69.6017 | K18: =$I$5 -> 58.171578 | L18: =K18-I18 -> -11.430122 | M18: =+M17+L18 -> -82.389072
A19: 7 | B19: =+B18-E$6 -> 23393.25 | C19: =+B19*($F$6/12) -> 58.483125 | D19: =+C19*$D$11 -> 2.0469094 | E19: =+C19*$E$11 -> 0.29241563 | F19: =+$F$11 -> 0.5 | G19: =+SUM(C19:F19) -> 61.32245 | H19: =+G19*$H$11 -> 7.358694 | I19: =+G19+H19 -> 68.681144 | K19: =$I$5 -> 58.171578 | L19: =K19-I19 -> -10.509566 | M19: =+M18+L19 -> -92.898638
A20: 8 | B20: =+B19-E$6 -> 23077.125 | C20: =+B20*($F$6/12) -> 57.692813 | D20: =+C20*$D$11 -> 2.0192484 | E20: =+C20*$E$11 -> 0.28846406 | F20: =+$F$11 -> 0.5 | G20: =+SUM(C20:F20) -> 60.500525 | H20: =+G20*$H$11 -> 7.260063 | I20: =+G20+H20 -> 67.760588 | K20: =$I$5 -> 58.171578 | L20: =K20-I20 -> -9.5890099 | M20: =+M19+L20 -> -102.48765
A21: 9 | B21: =+B20-E$6 -> 22761 | C21: =+B21*($F$6/12) -> 56.9025 | D21: =+C21*$D$11 -> 1.9915875 | E21: =+C21*$E$11 -> 0.2845125 | F21: =+$F$11 -> 0.5 | G21: =+SUM(C21:F21) -> 59.6786 | H21: =+G21*$H$11 -> 7.161432 | I21: =+G21+H21 -> 66.840032 | K21: =$I$5 -> 58.171578 | L21: =K21-I21 -> -8.6684539 | M21: =+M20+L21 -> -111.1561
A22: 10 | B22: =+B21-E$6 -> 22444.875 | C22: =+B22*($F$6/12) -> 56.112188 | D22: =+C22*$D$11 -> 1.9639266 | E22: =+C22*$E$11 -> 0.28056094 | F22: =+$F$11 -> 0.5 | G22: =+SUM(C22:F22) -> 58.856675 | H22: =+G22*$H$11 -> 7.062801 | I22: =+G22+H22 -> 65.919476 | K22: =$I$5 -> 58.171578 | L22: =K22-I22 -> -7.7478979 | M22: =+M21+L22 -> -118.904
A23: 11 | B23: =+B22-E$6 -> 22128.75 | C23: =+B23*($F$6/12) -> 55.321875 | D23: =+C23*$D$11 -> 1.9362656 | E23: =+C23*$E$11 -> 0.27660937 | F23: =+$F$11 -> 0.5 | G23: =+SUM(C23:F23) -> 58.03475 | H23: =+G23*$H$11 -> 6.96417 | I23: =+G23+H23 -> 64.99892 | K23: =$I$5 -> 58.171578 | L23: =K23-I23 -> -6.8273419 | M23: =+M22+L23 -> -125.73134
A24: 12 | B24: =+B23-E$6 -> 21812.625 | C24: =+B24*($F$6/12) -> 54.531562 | D24: =+C24*$D$11 -> 1.9086047 | E24: =+C24*$E$11 -> 0.27265781 | F24: =+$F$11 -> 0.5 | G24: =+SUM(C24:F24) -> 57.212825 | H24: =+G24*$H$11 -> 6.865539 | I24: =+G24+H24 -> 64.078364 | K24: =$I$5 -> 58.171578 | L24: =K24-I24 -> -5.9067859 | M24: =+M23+L24 -> -131.63813
A25: =IF($C$3>=2,A24+1,"") -> 13 | B25: =IF($C$3>=2,C7,"") -> 21496.5 | C25: =IF($C$3>=2,B25*($F$7/12),"") -> 53.74125 | D25: =IF($C$3>=2,C25*$D$11,"") -> 1.8809438 | E25: =IF($C$3>=2,C25*$E$11,"") -> 0.26870625 | F25: =IF($C$3>=2,$F$11,"") -> 0.5 | G25: =IF($C$3>=2,SUM(C25:F25),"") -> 56.3909 | H25: =IF($C$3>=2,G25*$H$11,"") -> 6.766908 | I25: =IF($C$3>=2,G25+H25,"") -> 63.157808 | K25: =$I$5 -> 58.171578 | L25: =K25-I25 -> -4.9862299 | M25: =IF($C$3>=2,M24+L25,"") -> -136.62436
A26: =IF($C$3>=2,A25+1,"") -> 14 | B26: =IF($C$3>=2,B25-E$7,"") -> 21317.362 | C26: =IF($C$3>=2,B26*($F$7/12),"") -> 53.293406 | D26: =IF($C$3>=2,C26*$D$11,"") -> 1.8652692 | E26: =IF($C$3>=2,C26*$E$11,"") -> 0.26646703 | F26: =IF($C$3>=2,$F$11,"") -> 0.5 | G26: =IF($C$3>=2,SUM(C26:F26),"") -> 55.925142 | H26: =IF($C$3>=2,G26*$H$11,"") -> 6.7110171 | I26: =IF($C$3>=2,G26+H26,"") -> 62.63616 | K26: =$I$5 -> 58.171578 | L26: =K26-I26 -> -4.4645815 | M26: =IF($C$3>=2,M25+L26,"") -> -141.08894
A27: =IF($C$3>=2,A26+1,"") -> 15 | B27: =IF($C$3>=2,B26-E$7,"") -> 21138.225 | C27: =IF($C$3>=2,B27*($F$7/12),"") -> 52.845562 | D27: =IF($C$3>=2,C27*$D$11,"") -> 1.8495947 | E27: =IF($C$3>=2,C27*$E$11,"") -> 0.26422781 | F27: =IF($C$3>=2,$F$11,"") -> 0.5 | G27: =IF($C$3>=2,SUM(C27:F27),"") -> 55.459385 | H27: =IF($C$3>=2,G27*$H$11,"") -> 6.6551262 | I27: =IF($C$3>=2,G27+H27,"") -> 62.114511 | K27: =$I$5 -> 58.171578 | L27: =K27-I27 -> -3.9429331 | M27: =IF($C$3>=2,M26+L27,"") -> -145.03187
A28: =IF($C$3>=2,A27+1,"") -> 16 | B28: =IF($C$3>=2,B27-E$7,"") -> 20959.087 | C28: =IF($C$3>=2,B28*($F$7/12),"") -> 52.397719 | D28: =IF($C$3>=2,C28*$D$11,"") -> 1.8339202 | E28: =IF($C$3>=2,C28*$E$11,"") -> 0.26198859 | F28: =IF($C$3>=2,$F$11,"") -> 0.5 | G28: =IF($C$3>=2,SUM(C28:F28),"") -> 54.993627 | H28: =IF($C$3>=2,G28*$H$11,"") -> 6.5992353 | I28: =IF($C$3>=2,G28+H28,"") -> 61.592863 | K28: =$I$5 -> 58.171578 | L28: =K28-I28 -> -3.4212847 | M28: =IF($C$3>=2,M27+L28,"") -> -148.45316
A29: =IF($C$3>=2,A28+1,"") -> 17 | B29: =IF($C$3>=2,B28-E$7,"") -> 20779.95 | C29: =IF($C$3>=2,B29*($F$7/12),"") -> 51.949875 | D29: =IF($C$3>=2,C29*$D$11,"") -> 1.8182456 | E29: =IF($C$3>=2,C29*$E$11,"") -> 0.25974937 | F29: =IF($C$3>=2,$F$11,"") -> 0.5 | G29: =IF($C$3>=2,SUM(C29:F29),"") -> 54.52787 | H29: =IF($C$3>=2,G29*$H$11,"") -> 6.5433444 | I29: =IF($C$3>=2,G29+H29,"") -> 61.071214 | K29: =$I$5 -> 58.171578 | L29: =K29-I29 -> -2.8996363 | M29: =IF($C$3>=2,M28+L29,"") -> -151.35279
A30: =IF($C$3>=2,A29+1,"") -> 18 | B30: =IF($C$3>=2,B29-E$7,"") -> 20600.812 | C30: =IF($C$3>=2,B30*($F$7/12),"") -> 51.502031 | D30: =IF($C$3>=2,C30*$D$11,"") -> 1.8025711 | E30: =IF($C$3>=2,C30*$E$11,"") -> 0.25751016 | F30: =IF($C$3>=2,$F$11,"") -> 0.5 | G30: =IF($C$3>=2,SUM(C30:F30),"") -> 54.062112 | H30: =IF($C$3>=2,G30*$H$11,"") -> 6.4874535 | I30: =IF($C$3>=2,G30+H30,"") -> 60.549566 | K30: =$I$5 -> 58.171578 | L30: =K30-I30 -> -2.3779879 | M30: =IF($C$3>=2,M29+L30,"") -> -153.73078
A31: =IF($C$3>=2,A30+1,"") -> 19 | B31: =IF($C$3>=2,B30-E$7,"") -> 20421.675 | C31: =IF($C$3>=2,B31*($F$7/12),"") -> 51.054187 | D31: =IF($C$3>=2,C31*$D$11,"") -> 1.7868966 | E31: =IF($C$3>=2,C31*$E$11,"") -> 0.25527094 | F31: =IF($C$3>=2,$F$11,"") -> 0.5 | G31: =IF($C$3>=2,SUM(C31:F31),"") -> 53.596355 | H31: =IF($C$3>=2,G31*$H$11,"") -> 6.4315626 | I31: =IF($C$3>=2,G31+H31,"") -> 60.027918 | K31: =$I$5 -> 58.171578 | L31: =K31-I31 -> -1.8563395 | M31: =IF($C$3>=2,M30+L31,"") -> -155.58712
A32: =IF($C$3>=2,A31+1,"") -> 20 | B32: =IF($C$3>=2,B31-E$7,"") -> 20242.537 | C32: =IF($C$3>=2,B32*($F$7/12),"") -> 50.606344 | D32: =IF($C$3>=2,C32*$D$11,"") -> 1.771222 | E32: =IF($C$3>=2,C32*$E$11,"") -> 0.25303172 | F32: =IF($C$3>=2,$F$11,"") -> 0.5 | G32: =IF($C$3>=2,SUM(C32:F32),"") -> 53.130597 | H32: =IF($C$3>=2,G32*$H$11,"") -> 6.3756717 | I32: =IF($C$3>=2,G32+H32,"") -> 59.506269 | K32: =$I$5 -> 58.171578 | L32: =K32-I32 -> -1.3346911 | M32: =IF($C$3>=2,M31+L32,"") -> -156.92181
A33: =IF($C$3>=2,A32+1,"") -> 21 | B33: =IF($C$3>=2,B32-E$7,"") -> 20063.4 | C33: =IF($C$3>=2,B33*($F$7/12),"") -> 50.1585 | D33: =IF($C$3>=2,C33*$D$11,"") -> 1.7555475 | E33: =IF($C$3>=2,C33*$E$11,"") -> 0.2507925 | F33: =IF($C$3>=2,$F$11,"") -> 0.5 | G33: =IF($C$3>=2,SUM(C33:F33),"") -> 52.66484 | H33: =IF($C$3>=2,G33*$H$11,"") -> 6.3197808 | I33: =IF($C$3>=2,G33+H33,"") -> 58.984621 | K33: =$I$5 -> 58.171578 | L33: =K33-I33 -> -0.81304273 | M33: =IF($C$3>=2,M32+L33,"") -> -157.73485
A34: =IF($C$3>=2,A33+1,"") -> 22 | B34: =IF($C$3>=2,B33-E$7,"") -> 19884.262 | C34: =IF($C$3>=2,B34*($F$7/12),"") -> 49.710656 | D34: =IF($C$3>=2,C34*$D$11,"") -> 1.739873 | E34: =IF($C$3>=2,C34*$E$11,"") -> 0.24855328 | F34: =IF($C$3>=2,$F$11,"") -> 0.5 | G34: =IF($C$3>=2,SUM(C34:F34),"") -> 52.199082 | H34: =IF($C$3>=2,G34*$H$11,"") -> 6.2638899 | I34: =IF($C$3>=2,G34+H34,"") -> 58.462972 | K34: =$I$5 -> 58.171578 | L34: =K34-I34 -> -0.29139433 | M34: =IF($C$3>=2,M33+L34,"") -> -158.02625
A35: =IF($C$3>=2,A34+1,"") -> 23 | B35: =IF($C$3>=2,B34-E$7,"") -> 19705.125 | C35: =IF($C$3>=2,B35*($F$7/12),"") -> 49.262812 | D35: =IF($C$3>=2,C35*$D$11,"") -> 1.7241984 | E35: =IF($C$3>=2,C35*$E$11,"") -> 0.24631406 | F35: =IF($C$3>=2,$F$11,"") -> 0.5 | G35: =IF($C$3>=2,SUM(C35:F35),"") -> 51.733325 | H35: =IF($C$3>=2,G35*$H$11,"") -> 6.207999 | I35: =IF($C$3>=2,G35+H35,"") -> 57.941324 | K35: =$I$5 -> 58.171578 | L35: =K35-I35 -> 0.23025407 | M35: =IF($C$3>=2,M34+L35,"") -> -157.79599
A36: =IF($C$3>=2,A35+1,"") -> 24 | B36: =IF($C$3>=2,B35-E$7,"") -> 19525.987 | C36: =IF($C$3>=2,B36*($F$7/12),"") -> 48.814969 | D36: =IF($C$3>=2,C36*$D$11,"") -> 1.7085239 | E36: =IF($C$3>=2,C36*$E$11,"") -> 0.24407484 | F36: =IF($C$3>=2,$F$11,"") -> 0.5 | G36: =IF($C$3>=2,SUM(C36:F36),"") -> 51.267567 | H36: =IF($C$3>=2,G36*$H$11,"") -> 6.1521081 | I36: =IF($C$3>=2,G36+H36,"") -> 57.419676 | K36: =$I$5 -> 58.171578 | L36: =K36-I36 -> 0.75190247 | M36: =IF($C$3>=2,M35+L36,"") -> -157.04409
A37: =IF($C$3>=3,A36+1,"") -> 25 | B37: =IF($C$3>=3,C8,"") -> 19346.85 | C37: =IF($C$3>=3,B37*($F$8/12),"") -> 48.367125 | D37: =IF($C$3>=3,C37*$D$11,"") -> 1.6928494 | E37: =IF($C$3>=3,C37*$E$11,"") -> 0.24183562 | F37: =IF($C$3>=3,$F$11,"") -> 0.5 | G37: =IF($C$3>=3,SUM(C37:F37),"") -> 50.80181 | H37: =IF($C$3>=3,G37*$H$11,"") -> 6.0962172 | I37: =IF($C$3>=3,G37+H37,"") -> 56.898027 | K37: =$I$5 -> 58.171578 | L37: =K37-I37 -> 1.2735509 | M37: =IF($C$3>=3,M36+L37,"") -> -155.77054
A38: =IF($C$3>=3,A37+1,"") -> 26 | B38: =IF($C$3>=3,B37-E$8,"") -> 19185.626 | C38: =IF($C$3>=3,B38*($F$8/12),"") -> 47.964066 | D38: =IF($C$3>=3,C38*$D$11,"") -> 1.6787423 | E38: =IF($C$3>=3,C38*$E$11,"") -> 0.23982033 | F38: =IF($C$3>=3,$F$11,"") -> 0.5 | G38: =IF($C$3>=3,SUM(C38:F38),"") -> 50.382628 | H38: =IF($C$3>=3,G38*$H$11,"") -> 6.0459154 | I38: =IF($C$3>=3,G38+H38,"") -> 56.428544 | K38: =$I$5 -> 58.171578 | L38: =K38-I38 -> 1.7430344 | M38: =IF($C$3>=3,M37+L38,"") -> -154.02751
A39: =IF($C$3>=3,A38+1,"") -> 27 | B39: =IF($C$3>=3,B38-E$8,"") -> 19024.402 | C39: =IF($C$3>=3,B39*($F$8/12),"") -> 47.561006 | D39: =IF($C$3>=3,C39*$D$11,"") -> 1.6646352 | E39: =IF($C$3>=3,C39*$E$11,"") -> 0.23780503 | F39: =IF($C$3>=3,$F$11,"") -> 0.5 | G39: =IF($C$3>=3,SUM(C39:F39),"") -> 49.963446 | H39: =IF($C$3>=3,G39*$H$11,"") -> 5.9956136 | I39: =IF($C$3>=3,G39+H39,"") -> 55.95906 | K39: =$I$5 -> 58.171578 | L39: =K39-I39 -> 2.212518 | M39: =IF($C$3>=3,M38+L39,"") -> -151.81499
A40: =IF($C$3>=3,A39+1,"") -> 28 | B40: =IF($C$3>=3,B39-E$8,"") -> 18863.179 | C40: =IF($C$3>=3,B40*($F$8/12),"") -> 47.157947 | D40: =IF($C$3>=3,C40*$D$11,"") -> 1.6505281 | E40: =IF($C$3>=3,C40*$E$11,"") -> 0.23578973 | F40: =IF($C$3>=3,$F$11,"") -> 0.5 | G40: =IF($C$3>=3,SUM(C40:F40),"") -> 49.544265 | H40: =IF($C$3>=3,G40*$H$11,"") -> 5.9453118 | I40: =IF($C$3>=3,G40+H40,"") -> 55.489577 | K40: =$I$5 -> 58.171578 | L40: =K40-I40 -> 2.6820015 | M40: =IF($C$3>=3,M39+L40,"") -> -149.13299
A41: =IF($C$3>=3,A40+1,"") -> 29 | B41: =IF($C$3>=3,B40-E$8,"") -> 18701.955 | C41: =IF($C$3>=3,B41*($F$8/12),"") -> 46.754887 | D41: =IF($C$3>=3,C41*$D$11,"") -> 1.6364211 | E41: =IF($C$3>=3,C41*$E$11,"") -> 0.23377444 | F41: =IF($C$3>=3,$F$11,"") -> 0.5 | G41: =IF($C$3>=3,SUM(C41:F41),"") -> 49.125083 | H41: =IF($C$3>=3,G41*$H$11,"") -> 5.89501 | I41: =IF($C$3>=3,G41+H41,"") -> 55.020093 | K41: =$I$5 -> 58.171578 | L41: =K41-I41 -> 3.1514851 | M41: =IF($C$3>=3,M40+L41,"") -> -145.9815
A42: =IF($C$3>=3,A41+1,"") -> 30 | B42: =IF($C$3>=3,B41-E$8,"") -> 18540.731 | C42: =IF($C$3>=3,B42*($F$8/12),"") -> 46.351828 | D42: =IF($C$3>=3,C42*$D$11,"") -> 1.622314 | E42: =IF($C$3>=3,C42*$E$11,"") -> 0.23175914 | F42: =IF($C$3>=3,$F$11,"") -> 0.5 | G42: =IF($C$3>=3,SUM(C42:F42),"") -> 48.705901 | H42: =IF($C$3>=3,G42*$H$11,"") -> 5.8447081 | I42: =IF($C$3>=3,G42+H42,"") -> 54.550609 | K42: =$I$5 -> 58.171578 | L42: =K42-I42 -> 3.6209687 | M42: =IF($C$3>=3,M41+L42,"") -> -142.36053
...
